<sdf version='1.7'>
  <model name='BeobotV3_arm'>
    <link name='dummy_link'>
      <inertial>
        <pose>-0.057619 3e-05 0.148542 0 -0 0</pose>
        <mass>29.5855</mass>
        <inertia>
          <ixx>1.08041</ixx>
          <ixy>7.71608e-05</ixy>
          <ixz>0.0950363</ixz>
          <iyy>1.01181</iyy>
          <iyz>-0.000182829</iyz>
          <izz>0.954227</izz>
        </inertia>
      </inertial>
      <collision name='dummy_link_fixed_joint_lump__base_link_collision'>
        <pose>0 0 0 0 -0 0</pose>
        <geometry>
          <mesh>
            <scale>1 1 1</scale>
            <uri>model://BeobotV3_arm/meshes/base_link.STL</uri>
          </mesh>
        </geometry>
        <surface>
          <contact>
            <ode>
              <kp>1e+07</kp>
              <kd>1</kd>
            </ode>
          </contact>
          <friction>
            <ode>
              <mu>0</mu>
              <mu2>0</mu2>
              <fdir1>1 0 0</fdir1>
            </ode>
          </friction>
        </surface>
      </collision>
      <collision name='dummy_link_fixed_joint_lump__Hokuyo_collision_1'>
        <pose>0.1162 0 0.099388 1.5708 -0 1.5708</pose>
        <geometry>
          <mesh>
            <scale>1 1 1</scale>
            <uri>model://BeobotV3_arm/meshes/Hokuyo.STL</uri>
          </mesh>
        </geometry>
      </collision>
      <collision name='dummy_link_fixed_joint_lump__Velodine_collision_2'>
        <pose>-0.0889 0 0.54034 1.5708 -0 3.14159</pose>
        <geometry>
          <mesh>
            <scale>1 1 1</scale>
            <uri>model://BeobotV3_arm/meshes/Velodine.STL</uri>
          </mesh>
        </geometry>
      </collision>
      <collision name='dummy_link_fixed_joint_lump__arm_base_collision_3'>
        <pose>-0.46908 0 0.100773 -1.5708 -0 3.14159</pose>
        <geometry>
          <mesh>
            <scale>1 1 1</scale>
            <uri>model://BeobotV3_arm/meshes/arm_base.STL</uri>
          </mesh>
        </geometry>
      </collision>
      <collision name='dummy_link_fixed_joint_lump__realsense_1_collision_4'>
        <pose>0.04226 -0.01 0.521339 1.5708 -0 1.5708</pose>
        <geometry>
          <mesh>
            <scale>1 1 1</scale>
            <uri>model://BeobotV3_arm/meshes/realsense_1.STL</uri>
          </mesh>
        </geometry>
      </collision>
      <collision name='dummy_link_fixed_joint_lump__realsense_2_collision_5'>
        <pose>-0.038859 0.12165 0.521339 1.5708 -0 2.82743</pose>
        <geometry>
          <mesh>
            <scale>1 1 1</scale>
            <uri>model://BeobotV3_arm/meshes/realsense_2.STL</uri>
          </mesh>
        </geometry>
      </collision>
      <collision name='dummy_link_fixed_joint_lump__realsense-3_collision_6'>
        <pose>-0.189133 0.085184 0.521339 1.5708 -0 -2.19911</pose>
        <geometry>
          <mesh>
            <scale>1 1 1</scale>
            <uri>model://BeobotV3_arm/meshes/realsense-3.STL</uri>
          </mesh>
        </geometry>
      </collision>
      <collision name='dummy_link_fixed_joint_lump__realsense-4_collision_7'>
        <pose>-0.200889 -0.069004 0.521339 1.5708 -0 -0.942478</pose>
        <geometry>
          <mesh>
            <scale>1 1 1</scale>
            <uri>model://BeobotV3_arm/meshes/realsense-4.STL</uri>
          </mesh>
        </geometry>
      </collision>
      <collision name='dummy_link_fixed_joint_lump__realsense-5_collision_8'>
        <pose>-0.05788 -0.127831 0.521339 1.5708 -0 0.314159</pose>
        <geometry>
          <mesh>
            <scale>1 1 1</scale>
            <uri>model://BeobotV3_arm/meshes/realsense-5.STL</uri>
          </mesh>
        </geometry>
      </collision>
      <visual name='dummy_link_fixed_joint_lump__base_link_visual'>
        <pose>0 0 0 0 -0 0</pose>
        <geometry>
          <mesh>
            <scale>1 1 1</scale>
            <uri>model://BeobotV3_arm/meshes/base_link.STL</uri>
          </mesh>
        </geometry>
      </visual>
      <visual name='dummy_link_fixed_joint_lump__Hokuyo_visual_1'>
        <pose>0.1162 0 0.099388 1.5708 -0 1.5708</pose>
        <geometry>
          <mesh>
            <scale>1 1 1</scale>
            <uri>model://BeobotV3_arm/meshes/Hokuyo.STL</uri>
          </mesh>
        </geometry>
      </visual>
      <visual name='dummy_link_fixed_joint_lump__Velodine_visual_2'>
        <pose>-0.0889 0 0.54034 1.5708 -0 3.14159</pose>
        <geometry>
          <mesh>
            <scale>1 1 1</scale>
            <uri>model://BeobotV3_arm/meshes/Velodine.STL</uri>
          </mesh>
        </geometry>
      </visual>
      <visual name='dummy_link_fixed_joint_lump__arm_base_visual_3'>
        <pose>-0.46908 0 0.100773 -1.5708 -0 3.14159</pose>
        <geometry>
          <mesh>
            <scale>1 1 1</scale>
            <uri>model://BeobotV3_arm/meshes/arm_base.STL</uri>
          </mesh>
        </geometry>
      </visual>
      <visual name='dummy_link_fixed_joint_lump__realsense_1_visual_4'>
        <pose>0.04226 -0.01 0.521339 1.5708 -0 1.5708</pose>
        <geometry>
          <mesh>
            <scale>1 1 1</scale>
            <uri>model://BeobotV3_arm/meshes/realsense_1.STL</uri>
          </mesh>
        </geometry>
      </visual>
      <visual name='dummy_link_fixed_joint_lump__realsense_2_visual_5'>
        <pose>-0.038859 0.12165 0.521339 1.5708 -0 2.82743</pose>
        <geometry>
          <mesh>
            <scale>1 1 1</scale>
            <uri>model://BeobotV3_arm/meshes/realsense_2.STL</uri>
          </mesh>
        </geometry>
      </visual>
      <visual name='dummy_link_fixed_joint_lump__realsense-3_visual_6'>
        <pose>-0.189133 0.085184 0.521339 1.5708 -0 -2.19911</pose>
        <geometry>
          <mesh>
            <scale>1 1 1</scale>
            <uri>model://BeobotV3_arm/meshes/realsense-3.STL</uri>
          </mesh>
        </geometry>
      </visual>
      <visual name='dummy_link_fixed_joint_lump__realsense-4_visual_7'>
        <pose>-0.200889 -0.069004 0.521339 1.5708 -0 -0.942478</pose>
        <geometry>
          <mesh>
            <scale>1 1 1</scale>
            <uri>model://BeobotV3_arm/meshes/realsense-4.STL</uri>
          </mesh>
        </geometry>
      </visual>
      <visual name='dummy_link_fixed_joint_lump__realsense-5_visual_8'>
        <pose>-0.05788 -0.127831 0.521339 1.5708 -0 0.314159</pose>
        <geometry>
          <mesh>
            <scale>1 1 1</scale>
            <uri>model://BeobotV3_arm/meshes/realsense-5.STL</uri>
          </mesh>
        </geometry>
      </visual>
      <gravity>1</gravity>
      <velocity_decay/>
    </link>
    <joint name='Caster Joint' type='revolute'>
      <pose relative_to='dummy_link'>-0.2489 0 0 1.5708 -0 1.5708</pose>
      <parent>dummy_link</parent>
      <child>Caster</child>
      <axis>
        <xyz>0 1 0</xyz>
        <limit>
          <lower>-1e+16</lower>
          <upper>1e+16</upper>
        </limit>
        <dynamics>
          <spring_reference>0</spring_reference>
          <spring_stiffness>0</spring_stiffness>
        </dynamics>
      </axis>
    </joint>
    <link name='Caster'>
      <pose relative_to='Caster Joint'>0 0 0 0 -0 0</pose>
      <inertial>
        <pose>-0 0.002048 -0.018119 0 -0 0</pose>
        <mass>0.0611311</mass>
        <inertia>
          <ixx>7.09576e-05</ixx>
          <ixy>-4.91477e-12</ixy>
          <ixz>5.15091e-13</ixz>
          <iyy>3.74419e-05</iyy>
          <iyz>-2.74891e-05</iyz>
          <izz>6.96806e-05</izz>
        </inertia>
      </inertial>
      <collision name='Caster_collision'>
        <pose>0 0 0 0 -0 0</pose>
        <geometry>
          <mesh>
            <scale>1 1 1</scale>
            <uri>model://BeobotV3_arm/meshes/Caster.STL</uri>
          </mesh>
        </geometry>
      </collision>
      <visual name='Caster_visual'>
        <pose>0 0 0 0 -0 0</pose>
        <geometry>
          <mesh>
            <scale>1 1 1</scale>
            <uri>model://BeobotV3_arm/meshes/Caster.STL</uri>
          </mesh>
        </geometry>
      </visual>
    </link>
    <joint name='CWheel Joint' type='revolute'>
      <pose relative_to='Caster'>0 -0.049142 -0.047513 -3.14159 0 0</pose>
      <parent>Caster</parent>
      <child>Caster Wheel</child>
      <axis>
        <xyz>1 0 0</xyz>
        <limit>
          <lower>-1e+16</lower>
          <upper>1e+16</upper>
        </limit>
        <dynamics>
          <spring_reference>0</spring_reference>
          <spring_stiffness>0</spring_stiffness>
        </dynamics>
      </axis>
    </joint>
    <link name='Caster Wheel'>
      <pose relative_to='CWheel Joint'>0 0 0 0 -0 0</pose>
      <inertial>
        <pose>-0 0 0 0 -0 0</pose>
        <mass>0.122723</mass>
        <inertia>
          <ixx>8.99332e-05</ixx>
          <ixy>7.96185e-22</ixy>
          <ixz>-1.11135e-37</ixz>
          <iyy>5.21169e-05</iyy>
          <iyz>4.3069e-38</iyz>
          <izz>5.21169e-05</izz>
        </inertia>
      </inertial>
      <collision name='Caster Wheel_collision'>
        <pose>0 0 0 0 -0 0</pose>
        <geometry>
          <mesh>
            <scale>1 1 1</scale>
            <uri>model://BeobotV3_arm/meshes/Caster Wheel.STL</uri>
          </mesh>
        </geometry>
      </collision>
      <visual name='Caster Wheel_visual'>
        <pose>0 0 0 0 -0 0</pose>
        <geometry>
          <mesh>
            <scale>1 1 1</scale>
            <uri>model://BeobotV3_arm/meshes/Caster Wheel.STL</uri>
          </mesh>
        </geometry>
      </visual>
    </link>
    <joint name='arm_joint_1' type='revolute'>
      <pose relative_to='dummy_link'>-0.5082 -0 0.156698 -1.5708 -0 1.5708</pose>
      <parent>dummy_link</parent>
      <child>arm_link_1</child>
      <axis>
        <xyz>0 1 0</xyz>
        <limit>
          <lower>-1e+16</lower>
          <upper>1e+16</upper>
        </limit>
        <dynamics>
          <damping>0.5</damping>
          <friction>0</friction>
          <spring_reference>0</spring_reference>
          <spring_stiffness>0</spring_stiffness>
        </dynamics>
      </axis>
    </joint>
    <link name='arm_link_1'>
      <pose relative_to='arm_joint_1'>0 0 0 0 -0 0</pose>
      <inertial>
        <pose>0 -0.019 -0.022782 0 -0 0</pose>
        <mass>0.0178647</mass>
        <inertia>
          <ixx>3.44196e-05</ixx>
          <ixy>-2.32645e-22</ixy>
          <ixz>5.19287e-21</ixz>
          <iyy>3.2416e-05</iyy>
          <iyz>2.39613e-21</iyz>
          <izz>5.5291e-06</izz>
        </inertia>
      </inertial>
      <collision name='arm_link_1_collision'>
        <pose>0 0 0 0 -0 0</pose>
        <geometry>
          <mesh>
            <scale>1 1 1</scale>
            <uri>model://BeobotV3_arm/meshes/arm_link_1.STL</uri>
          </mesh>
        </geometry>
        <surface>
          <contact>
            <ode/>
          </contact>
          <friction>
            <ode/>
          </friction>
        </surface>
      </collision>
      <visual name='arm_link_1_visual'>
        <pose>0 0 0 0 -0 0</pose>
        <geometry>
          <mesh>
            <scale>1 1 1</scale>
            <uri>model://BeobotV3_arm/meshes/arm_link_1.STL</uri>
          </mesh>
        </geometry>
      </visual>
      <gravity>1</gravity>
      <velocity_decay/>
      <sensor name='arm_link_1_contact' type='contact'>
        <update_rate>50</update_rate>
        <always_on>1</always_on>
        <contact>
          <collision>arm_link_1_collision</collision>
          <topic>__default_topic__</topic>
        </contact>
        <plugin name='ros_bumper_0' filename='libgazebo_ros_bumper.so'>
          <bumperTopicName>arm_link1_collision</bumperTopicName>
          <frameName>arm_link_1</frameName>
        </plugin>
      </sensor>
    </link>
    <joint name='arm_joint_2' type='revolute'>
      <pose relative_to='arm_link_1'>0 -0.019 0 0 -0.109072 1.5708</pose>
      <parent>arm_link_1</parent>
      <child>arm_link_2</child>
      <axis>
        <xyz>0 1 0</xyz>
        <limit>
          <lower>-1e+16</lower>
          <upper>1e+16</upper>
        </limit>
        <dynamics>
          <damping>0.5</damping>
          <friction>0</friction>
          <spring_reference>0</spring_reference>
          <spring_stiffness>0</spring_stiffness>
        </dynamics>
      </axis>
    </joint>
    <link name='arm_link_2'>
      <pose relative_to='arm_joint_2'>0 0 0 0 -0 0</pose>
      <inertial>
        <pose>-0.121 -0.030796 -0 0 -0 0</pose>
        <mass>0.0649301</mass>
        <inertia>
          <ixx>3.22587e-05</ixx>
          <ixy>-2.47234e-19</ixy>
          <ixz>-6.92449e-20</ixz>
          <iyy>0.000476962</iyy>
          <iyz>-1.21028e-20</iyz>
          <izz>0.000507343</izz>
        </inertia>
      </inertial>
      <collision name='arm_link_2_collision'>
        <pose>0 0 0 0 -0 0</pose>
        <geometry>
          <mesh>
            <scale>1 1 1</scale>
            <uri>model://BeobotV3_arm/meshes/arm_link_2.STL</uri>
          </mesh>
        </geometry>
        <surface>
          <contact>
            <ode/>
          </contact>
          <friction>
            <ode/>
          </friction>
        </surface>
      </collision>
      <visual name='arm_link_2_visual'>
        <pose>0 0 0 0 -0 0</pose>
        <geometry>
          <mesh>
            <scale>1 1 1</scale>
            <uri>model://BeobotV3_arm/meshes/arm_link_2.STL</uri>
          </mesh>
        </geometry>
      </visual>
      <gravity>1</gravity>
      <velocity_decay/>
      <sensor name='arm_link_2_contact' type='contact'>
        <update_rate>50</update_rate>
        <always_on>1</always_on>
        <contact>
          <collision>arm_link_2_collision</collision>
          <topic>__default_topic__</topic>
        </contact>
        <plugin name='ros_bumper_1' filename='libgazebo_ros_bumper.so'>
          <bumperTopicName>arm_link2_collision</bumperTopicName>
          <frameName>arm_link_2</frameName>
        </plugin>
      </sensor>
    </link>
    <joint name='arm_joint_3' type='revolute'>
      <pose relative_to='arm_link_2'>-0.242 0 0 1.86869 -0 -1.5708</pose>
      <parent>arm_link_2</parent>
      <child>arm_link_3</child>
      <axis>
        <xyz>1 0 0</xyz>
        <limit>
          <lower>-1e+16</lower>
          <upper>1e+16</upper>
        </limit>
        <dynamics>
          <damping>0.5</damping>
          <friction>0</friction>
          <spring_reference>0</spring_reference>
          <spring_stiffness>0</spring_stiffness>
        </dynamics>
      </axis>
    </joint>
    <link name='arm_link_3'>
      <pose relative_to='arm_joint_3'>0 0 0 0 -0 0</pose>
      <inertial>
        <pose>0 0 -0.14258 0 -0 0</pose>
        <mass>0.0575915</mass>
        <inertia>
          <ixx>8.87747e-05</ixx>
          <ixy>4.55303e-21</ixy>
          <ixz>2.63232e-21</ixz>
          <iyy>8.44654e-05</iyy>
          <iyz>6.26804e-20</iyz>
          <izz>1.22592e-05</izz>
        </inertia>
      </inertial>
      <collision name='arm_link_3_collision'>
        <pose>0 0 0 0 -0 0</pose>
        <geometry>
          <mesh>
            <scale>1 1 1</scale>
            <uri>model://BeobotV3_arm/meshes/arm_link_3.STL</uri>
          </mesh>
        </geometry>
        <surface>
          <contact>
            <ode/>
          </contact>
          <friction>
            <ode/>
          </friction>
        </surface>
      </collision>
      <visual name='arm_link_3_visual'>
        <pose>0 0 0 0 -0 0</pose>
        <geometry>
          <mesh>
            <scale>1 1 1</scale>
            <uri>model://BeobotV3_arm/meshes/arm_link_3.STL</uri>
          </mesh>
        </geometry>
      </visual>
      <gravity>1</gravity>
      <velocity_decay/>
      <sensor name='arm_link_3_contact' type='contact'>
        <update_rate>50</update_rate>
        <always_on>1</always_on>
        <contact>
          <collision>arm_link_3_collision</collision>
          <topic>__default_topic__</topic>
        </contact>
        <plugin name='ros_bumper_2' filename='libgazebo_ros_bumper.so'>
          <bumperTopicName>arm_link3_collision</bumperTopicName>
          <frameName>arm_link_3</frameName>
        </plugin>
      </sensor>
    </link>
    <joint name='hand_joint' type='revolute'>
      <pose relative_to='arm_link_3'>0 0 -0.28516 -1.5708 0.812051 -1.5708</pose>
      <parent>arm_link_3</parent>
      <child>hand</child>
      <axis>
        <xyz>0 0 1</xyz>
        <limit>
          <lower>-1e+16</lower>
          <upper>1e+16</upper>
        </limit>
        <dynamics>
          <damping>0.5</damping>
          <friction>0</friction>
          <spring_reference>0</spring_reference>
          <spring_stiffness>0</spring_stiffness>
        </dynamics>
      </axis>
    </joint>
    <link name='hand'>
      <pose relative_to='hand_joint'>0 0 0 0 -0 0</pose>
      <inertial>
        <pose>-0.137649 -0.017487 -0.018527 0 -0 0</pose>
        <mass>0.0773862</mass>
        <inertia>
          <ixx>0.00107322</ixx>
          <ixy>-0.000125355</ixy>
          <ixz>3.9749e-05</ixz>
          <iyy>0.00155655</iyy>
          <iyz>6.73554e-06</iyz>
          <izz>0.00158356</izz>
        </inertia>
      </inertial>
      <collision name='hand_collision'>
        <pose>0 0 0 0 -0 0</pose>
        <geometry>
          <mesh>
            <scale>1 1 1</scale>
            <uri>model://BeobotV3_arm/meshes/hand.STL</uri>
          </mesh>
        </geometry>
        <surface>
          <contact>
            <ode/>
          </contact>
          <friction>
            <ode/>
          </friction>
        </surface>
      </collision>
      <collision name='hand_tip_collision_1'>
        <pose>-0.25 -0.06 -0.01 0 -0 0.45</pose>
        <geometry>
          <box>
            <size>0.001 0.001 0.001</size>
          </box>
        </geometry>
        <surface>
          <contact>
            <ode/>
          </contact>
          <friction>
            <ode/>
          </friction>
        </surface>
      </collision>
      <visual name='hand_visual'>
        <pose>0 0 0 0 -0 0</pose>
        <geometry>
          <mesh>
            <scale>1 1 1</scale>
            <uri>model://BeobotV3_arm/meshes/hand.STL</uri>
          </mesh>
        </geometry>
      </visual>
      <visual name='hand_tip_visual_1'>
        <pose>-0.25 -0.06 -0.01 0 -0 0.45</pose>
        <geometry>
          <box>
            <size>0.001 0.001 0.001</size>
          </box>
        </geometry>
      </visual>
      <gravity>1</gravity>
      <velocity_decay/>
      <sensor name='hand_contact' type='contact'>
        <update_rate>50</update_rate>
        <always_on>1</always_on>
        <contact>
          <collision>hand_collision</collision>
          <topic>__default_topic__</topic>
        </contact>
        <plugin name='ros_bumper_3' filename='libgazebo_ros_bumper.so'>
          <bumperTopicName>hand_collision</bumperTopicName>
          <frameName>hand</frameName>
        </plugin>
      </sensor>
    </link>
    <joint name='left_wheel_joint' type='revolute'>
      <pose relative_to='dummy_link'>0 0.23535 0 1.5708 -0 3.14159</pose>
      <parent>dummy_link</parent>
      <child>left_wheel</child>
      <axis>
        <xyz>0 0 1</xyz>
        <limit>
          <lower>-1e+16</lower>
          <upper>1e+16</upper>
        </limit>
        <dynamics>
          <spring_reference>0</spring_reference>
          <spring_stiffness>0</spring_stiffness>
        </dynamics>
      </axis>
    </joint>
    <link name='left_wheel'>
      <pose relative_to='left_wheel_joint'>0 0 0 0 -0 0</pose>
      <inertial>
        <pose>0 0 0.025 0 -0 0</pose>
        <mass>0.963878</mass>
        <inertia>
          <ixx>0.00173116</ixx>
          <ixy>9.09443e-37</ixy>
          <ixz>7.05861e-22</ixz>
          <iyy>0.00173116</iyy>
          <iyz>7.62311e-37</iyz>
          <izz>0.00310961</izz>
        </inertia>
      </inertial>
      <collision name='left_wheel_collision'>
        <pose>0 0 0 0 -0 0</pose>
        <geometry>
          <mesh>
            <scale>1 1 1</scale>
            <uri>model://BeobotV3_arm/meshes/left_wheel.STL</uri>
          </mesh>
        </geometry>
        <surface>
          <contact>
            <ode>
              <kp>1e+07</kp>
              <kd>1</kd>
            </ode>
          </contact>
          <friction>
            <ode>
              <mu>1</mu>
              <mu2>1</mu2>
              <fdir1>1 0 0</fdir1>
            </ode>
          </friction>
        </surface>
      </collision>
      <visual name='left_wheel_visual'>
        <pose>0 0 0 0 -0 0</pose>
        <geometry>
          <mesh>
            <scale>1 1 1</scale>
            <uri>model://BeobotV3_arm/meshes/left_wheel.STL</uri>
          </mesh>
        </geometry>
      </visual>
      <gravity>1</gravity>
      <velocity_decay/>
    </link>
    <joint name='right_wheel_joint' type='revolute'>
      <pose relative_to='dummy_link'>0 -0.23535 0 1.5708 -0 3.14159</pose>
      <parent>dummy_link</parent>
      <child>right_wheel</child>
      <axis>
        <xyz>0 0 1</xyz>
        <limit>
          <lower>-1e+16</lower>
          <upper>1e+16</upper>
        </limit>
        <dynamics>
          <spring_reference>0</spring_reference>
          <spring_stiffness>0</spring_stiffness>
        </dynamics>
      </axis>
    </joint>
    <link name='right_wheel'>
      <pose relative_to='right_wheel_joint'>0 0 0 0 -0 0</pose>
      <inertial>
        <pose>0 0 -0.025 0 -0 0</pose>
        <mass>0.963878</mass>
        <inertia>
          <ixx>0.00173116</ixx>
          <ixy>-5.14894e-36</ixy>
          <ixz>-1.30594e-21</ixz>
          <iyy>0.00173116</iyy>
          <iyz>5.86568e-36</iyz>
          <izz>0.00310961</izz>
        </inertia>
      </inertial>
      <collision name='right_wheel_collision'>
        <pose>0 0 0 0 -0 0</pose>
        <geometry>
          <mesh>
            <scale>1 1 1</scale>
            <uri>model://BeobotV3_arm/meshes/right_wheel.STL</uri>
          </mesh>
        </geometry>
        <surface>
          <contact>
            <ode>
              <kp>1e+07</kp>
              <kd>1</kd>
            </ode>
          </contact>
          <friction>
            <ode>
              <mu>1</mu>
              <mu2>1</mu2>
              <fdir1>1 0 0</fdir1>
            </ode>
          </friction>
        </surface>
      </collision>
      <visual name='right_wheel_visual'>
        <pose>0 0 0 0 -0 0</pose>
        <geometry>
          <mesh>
            <scale>1 1 1</scale>
            <uri>model://BeobotV3_arm/meshes/right_wheel.STL</uri>
          </mesh>
        </geometry>
      </visual>
      <gravity>1</gravity>
      <velocity_decay/>
    </link>
    <static>0</static>
    <plugin name='gazebo_ros_control' filename='libgazebo_ros_control.so'>
      <robotNamespace>/</robotNamespace>
    </plugin>
  </model>
</sdf>
